Workbook
Name Slicer_Continent: #N/A

Sheet Sales
A1: Order ID | B1: Date and Time | C1: Product ID | D1: Customer ID | E1: Category | F1: Payment Method | G1: Selling Price | H1: Quantity | I1: Selling Price Per Commodity | J1: Profit | K1: Days of Week
A2: ORD1 | B2: 45431.301 | C2: PROD196 | D2: CUST480 | E2: Fashion | F2: Credit Card | G2: 1879.16 | H2: 9 | I2: =G2/H2 -> 208.79556 | J2: =(Sales[[#This Row],[Selling Price Per Commodity]]-VLOOKUP(C2,Products!A:E,4, FALSE))*Sales[[#This Row],[Quantity]]/10 -> -251.14 | K2: =WEEKDAY(Sales[[#This Row],[Date and Time]],2) -> 7
A3: ORD2 | B3: 45604.838 | C3: PROD52 | D3: CUST978 | E3: Electronics | F3: Credit Card | G3: 1564.59 | H3: 6 | I3: =G3/H3 -> 260.765 | J3: =(Sales[[#This Row],[Selling Price Per Commodity]]-VLOOKUP(C3,Products!A:E,4, FALSE))*Sales[[#This Row],[Quantity]]/10 -> 113.577 | K3: =WEEKDAY(Sales[[#This Row],[Date and Time]],2) -> 5
A4: ORD3 | B4: 45515.831 | C4: PROD128 | D4: CUST189 | E4: Home Appliances | F4: Bank Transfer | G4: 702.1 | H4: 9 | I4: =G4/H4 -> 78.011111 | J4: =(Sales[[#This Row],[Selling Price Per Commodity]]-VLOOKUP(C4,Products!A:E,4, FALSE))*Sales[[#This Row],[Quantity]]/10 -> -384.326 | K4: =WEEKDAY(Sales[[#This Row],[Date and Time]],2) -> 7
A5: ORD4 | B5: 45442.533 | C5: PROD126 | D5: CUST171 | E5: Electronics | F5: Debit Card | G5: 737.92 | H5: 6 | I5: =G5/H5 -> 122.98667 | J5: =(Sales[[#This Row],[Selling Price Per Commodity]]-VLOOKUP(C5,Products!A:E,4, FALSE))*Sales[[#This Row],[Quantity]]/10 -> -289.388 | K5: =WEEKDAY(Sales[[#This Row],[Date and Time]],2) -> 4
A6: ORD5 | B6: 45486.727 | C6: PROD65 | D6: CUST255 | E6: Toys | F6: PayPal | G6: 1749.17 | H6: 5 | I6: =G6/H6 -> 349.834 | J6: =(Sales[[#This Row],[Selling Price Per Commodity]]-VLOOKUP(C6,Products!A:E,4, FALSE))*Sales[[#This Row],[Quantity]]/10 -> -312.193 | K6: =WEEKDAY(Sales[[#This Row],[Date and Time]],2) -> 6
A7: ORD6 | B7: 45582.724 | C7: PROD121 | D7: CUST552 | E7: Fashion | F7: PayPal | G7: 1706.03 | H7: 5 | I7: =G7/H7 -> 341.206 | J7: =(Sales[[#This Row],[Selling Price Per Commodity]]-VLOOKUP(C7,Products!A:E,4, FALSE))*Sales[[#This Row],[Quantity]]/10 -> -226.967 | K7: =WEEKDAY(Sales[[#This Row],[Date and Time]],2) -> 4
A8: ORD7 | B8: 45420.238 | C8: PROD47 | D8: CUST814 | E8: Fashion | F8: Credit Card | G8: 646.26 | H8: 1 | I8: =G8/H8 -> 646.26 | J8: =(Sales[[#This Row],[Selling Price Per Commodity]]-VLOOKUP(C8,Products!A:E,4, FALSE))*Sales[[#This Row],[Quantity]]/10 -> -17.552 | K8: =WEEKDAY(Sales[[#This Row],[Date and Time]],2) -> 3
A9: ORD8 | B9: 45468.527 | C9: PROD2 | D9: CUST739 | E9: Toys | F9: Cash | G9: 1292.07 | H9: 10 | I9: =G9/H9 -> 129.207 | J9: =(Sales[[#This Row],[Selling Price Per Commodity]]-VLOOKUP(C9,Products!A:E,4, FALSE))*Sales[[#This Row],[Quantity]]/10 -> -124.403 | K9: =WEEKDAY(Sales[[#This Row],[Date and Time]],2) -> 2
A10: ORD9 | B10: 45593.676 | C10: PROD137 | D10: CUST920 | E10: Home Appliances | F10: Bank Transfer | G10: 125.1 | H10: 1 | I10: =G10/H10 -> 125.1 | J10: =(Sales[[#This Row],[Selling Price Per Commodity]]-VLOOKUP(C10,Products!A:E,4, FALSE))*Sales[[#This Row],[Quantity]]/10 -> -48.732 | K10: =WEEKDAY(Sales[[#This Row],[Date and Time]],2) -> 1
A11: ORD10 | B11: 45323.652 | C11: PROD136 | D11: CUST28 | E11: Books | F11: Debit Card | G11: 281.18 | H11: 6 | I11: =G11/H11 -> 46.863333 | J11: =(Sales[[#This Row],[Selling Price Per Commodity]]-VLOOKUP(C11,Products!A:E,4, FALSE))*Sales[[#This Row],[Quantity]]/10 -> -107.794 | K11: =WEEKDAY(Sales[[#This Row],[Date and Time]],2) -> 4
A12: ORD11 | B12: 45348.664 | C12: PROD104 | D12: CUST110 | E12: Books | F12: Bank Transfer | G12: 1247.8 | H12: 3 | I12: =G12/H12 -> 415.93333 | J12: =(Sales[[#This Row],[Selling Price Per Commodity]]-VLOOKUP(C12,Products!A:E,4, FALSE))*Sales[[#This Row],[Quantity]]/10 -> 31.717 | K12: =WEEKDAY(Sales[[#This Row],[Date and Time]],2) -> 1
A13: ORD12 | B13: 45571.87 | C13: PROD165 | D13: CUST909 | E13: Books | F13: Credit Card | G13: 202.97 | H13: 1 | I13: =G13/H13 -> 202.97 | J13: =(Sales[[#This Row],[Selling Price Per Commodity]]-VLOOKUP(C13,Products!A:E,4, FALSE))*Sales[[#This Row],[Quantity]]/10 -> -36.06 | K13: =WEEKDAY(Sales[[#This Row],[Date and Time]],2) -> 7
... A7001: ORD7000 | B7001: 45421.478 | C7001: PROD49 | D7001: CUST87 | E7001: Electronics | F7001: Debit Card | G7001: 1569.49 | H7001: 2 | I7001: =G7001/H7001 -> 784.745 | J7001: =(Sales[[#This Row],[Selling Price Per Commodity]]-VLOOKUP(C7001,Products!A:E,4, FALSE))*Sales[[#This Row],[Quantity]]/10 -> 76.553 | K7001: =WEEKDAY(Sales[[#This Row],[Date and Time]],2) -> 4

Sheet Products
A1: Product ID | B1: Product Name | C1: Company | D1: Cost Price | E1: Cost Price | G1: Cost Price
A2: PROD1 | B2: Canon DSLR | C2: Dyson | D2: 435.29 | E2: =RANDBETWEEN(1,100) -> 81 | G2: 435.29
A3: PROD2 | B3: Sony Headphones | C3: Samsung | D3: 253.61 | E3: =RANDBETWEEN(1,100) -> 19 | G3: 253.61
A4: PROD3 | B4: Philips Air Fryer | C4: KitchenAid | D4: 27.63 | E4: =RANDBETWEEN(1,100) -> 67 | G4: 27.63
A5: PROD4 | B5: Lego Star Wars Set | C5: Apple | D5: 454.08 | E5: =RANDBETWEEN(1,100) -> 47 | G5: 454.08
A6: PROD5 | B6: Samsung Refrigerator | C6: Dyson | D6: 809.47 | E6: =RANDBETWEEN(1,100) -> 21 | G6: 809.47
A7: PROD6 | B7: HP Printer | C7: Bose | D7: 96.13 | E7: =RANDBETWEEN(1,100) -> 24 | G7: 96.13
A8: PROD7 | B8: Samsung Galaxy S22 | C8: IKEA | D8: 157.37 | E8: =RANDBETWEEN(1,100) -> 43 | G8: 157.37
A9: PROD8 | B9: Apple Watch | C9: Asus | D9: 851.56 | E9: =RANDBETWEEN(1,100) -> 61 | G9: 851.56
A10: PROD9 | B10: IKEA Chair | C10: Apple | D10: 481 | E10: =RANDBETWEEN(1,100) -> 44 | G10: 481
A11: PROD10 | B11: Samsung Refrigerator | C11: HP | D11: 438.5 | E11: =RANDBETWEEN(1,100) -> 69 | G11: 438.5
A12: PROD11 | B12: HP Printer | C12: Nike | D12: 595.51 | E12: =RANDBETWEEN(1,100) -> 73 | G12: 595.51
A13: PROD12 | B13: Apple Watch | C13: Lego | D13: 132.39 | E13: =RANDBETWEEN(1,100) -> 47 | G13: 132.39
... A201: PROD200 | B201: Sony Headphones | C201: Levi’s | D201: 606.07 | E201: =RANDBETWEEN(1,100) -> 98 | G201: 606.07

Sheet Customer
A1: Customer ID | B1: Name | C1: Gender | D1: Age | E1: Country | F1: Continent | G1: City
A2: CUST1 | B2: Vicki Wright | C2: Female | D2: 26 | E2: Panama | F2: Europe | G2: Port John
A3: CUST2 | B3: Stephanie Castro | C3: Female | D3: 49 | E3: Madagascar | F3: North America | G3: Joshuafort
A4: CUST3 | B4: Ronald Graham | C4: Male | D4: 56 | E4: Cote d'Ivoire | F4: South America | G4: East Shannon
A5: CUST4 | B5: David White | C5: Female | D5: 60 | E5: United Arab Emirates | F5: Europe | G5: Omarmouth
A6: CUST5 | B6: Jerry Gonzalez | C6: Female | D6: 21 | E6: British Indian Ocean Territory (Chagos Archipelago) | F6: Europe | G6: New Maryside
A7: CUST6 | B7: John Jordan | C7: Male | D7: 56 | E7: Cameroon | F7: Africa | G7: South Ashley
A8: CUST7 | B8: Kevin Kaiser | C8: Female | D8: 34 | E8: Saint Barthelemy | F8: Asia | G8: Schmidthaven
A9: CUST8 | B9: Stacey Jimenez | C9: Male | D9: 39 | E9: Iraq | F9: North America | G9: Bennettview
A10: CUST9 | B10: Zachary Williams | C10: Male | D10: 60 | E10: Saint Vincent and the Grenadines | F10: South America | G10: Crawfordport
A11: CUST10 | B11: Casey Clark | C11: Male | D11: 28 | E11: Morocco | F11: Oceania | G11: Port Brandontown
A12: CUST11 | B12: James Mills | C12: Male | D12: 36 | E12: Palestinian Territory | F12: North America | G12: Lake Daltonton
A13: CUST12 | B13: Jared Johnson | C13: Male | D13: 36 | E13: Guatemala | F13: Asia | G13: Oscarberg
... A1001: CUST1000 | B1001: Samantha Wilkinson | C1001: Male | D1001: 57 | E1001: Nigeria | F1001: Asia | G1001: East Anthonyfort

Sheet Dashboard

Sheet Sheet2
A3: Cards :- Total Sales, Total customers, Total Country Dealing, Total Categories Dealing, Total Profit | C3: Total sales | D3: Total Customers | E3: Total Country Dealing | F3: Total caregory Dealing | G3: Total Profit
A4: Visual to show Sales and Profit Over time. | C4: 1112975.4 | D4: 162 | E4: 124 | F4: 5 | G4: -198873.15
A5: Sales across Days of week | I5: Row Labels | J5: Sum of Profit
A6: Male and Female Customer Sales in each Category | C6: Sum of Selling Price | D6: Column Labels | I6: Books | J6: -34252.257
A7: Customer Bunch Analysis by Country | C7: Row Labels | D7: Female | E7: Male | F7: Grand Total | I7: Electronics | J7: -40861.911
A8: Contribution of each Category to total profit | C8: Books | D8: 111151.65 | E8: 103926.31 | F8: 215077.96 | I8: Fashion | J8: -43178.963
A9: Contribution of company to Overall Product Line | C9: Electronics | D9: 112678.76 | E9: 121642.39 | F9: 234321.15 | I9: Home Appliances | J9: -40655.199
C10: Fashion | D10: 112866.96 | E10: 123037.68 | F10: 235904.64 | I10: Toys | J10: -39924.817
C11: Home Appliances | D11: 122644.67 | E11: 87195.61 | F11: 209840.28 | I11: Grand Total | J11: -198873.15
C12: Toys | D12: 124006.42 | E12: 93824.99 | F12: 217831.41
A13: All The above things should change with reespect to continents | C13: Grand Total | D13: 583348.46 | E13: 529626.98 | F13: 1112975.4
I14: Row Labels | J14: Count of Product ID
I15: Adidas | J15: 11
I16: Apple | J16: 16
C17: Row Labels | D17: Count of Customer ID | I17: Asus | J17: 19
C18: Afghanistan | D18: 1 | I18: Bose | J18: 11
C19: Albania | D19: 2 | I19: Canon | J19: 9
C20: Andorra | D20: 2 | I20: Dell | J20: 6
C21: Anguilla | D21: 1 | I21: Dyson | J21: 9
C22: Argentina | D22: 1 | I22: Fitbit | J22: 3
C23: Aruba | D23: 2 | I23: HP | J23: 18
C24: Australia | D24: 2 | I24: IKEA | J24: 12
C25: Austria | D25: 3 | I25: KitchenAid | J25: 13
C26: Bahrain | D26: 2 | I26: Lego | J26: 12
C27: Belgium | D27: 1 | I27: Levi’s | J27: 7
C28: Bermuda | D28: 2 | I28: LG | J28: 11
C29: Bhutan | D29: 1 | I29: Nike | J29: 6
... C35: Burundi | D35: 1 | I35: Grand Total | J35: 200
C36: Cambodia | D36: 1
C37: Cameroon | D37: 1
C38: Cayman Islands | D38: 2
C39: Chad | D39: 2
C40: Chile | D40: 1
C41: Christmas Island | D41: 1
C42: Cocos (Keeling) Islands | D42: 1
C43: Colombia | D43: 1
C44: Comoros | D44: 1
C45: Cyprus | D45: 1
C46: Czech Republic | D46: 1
C47: Dominica | D47: 1
...
